Traceback (most recent call last):
  File "C:\Users\zimme\miniconda3\envs\tf\lib\site-packages\jupyter_cache\executors\utils.py", line 51, in single_nb_execution
    executenb(
  File "C:\Users\zimme\miniconda3\envs\tf\lib\site-packages\nbclient\client.py", line 1204, in execute
    return NotebookClient(nb=nb, resources=resources, km=km, **kwargs).execute()
  File "C:\Users\zimme\miniconda3\envs\tf\lib\site-packages\nbclient\util.py", line 84, in wrapped
    return just_run(coro(*args, **kwargs))
  File "C:\Users\zimme\miniconda3\envs\tf\lib\site-packages\nbclient\util.py", line 62, in just_run
    return loop.run_until_complete(coro)
  File "C:\Users\zimme\miniconda3\envs\tf\lib\asyncio\base_events.py", line 646, in run_until_complete
    return future.result()
  File "C:\Users\zimme\miniconda3\envs\tf\lib\site-packages\nbclient\client.py", line 663, in async_execute
    await self.async_execute_cell(
  File "C:\Users\zimme\miniconda3\envs\tf\lib\site-packages\nbclient\client.py", line 965, in async_execute_cell
    await self._check_raise_for_error(cell, cell_index, exec_reply)
  File "C:\Users\zimme\miniconda3\envs\tf\lib\site-packages\nbclient\client.py", line 862, in _check_raise_for_error
    raise CellExecutionError.from_cell_and_msg(cell, exec_reply_content)
nbclient.exceptions.CellExecutionError: An error occurred while executing the following cell:
------------------
err
fig, ax = plt.subplots()
point = (0.1, 0.2)
ax.plot(point[0],point[1],'.')
trans1 = ax.transData.transform(point)
trans2 = ax.transAxes.inverted().transform(trans1)
print(ax.get_xlim(), trans1,trans2)
------------------

[1;31m---------------------------------------------------------------------------[0m
[1;31mNameError[0m                                 Traceback (most recent call last)
Input [1;32mIn [3][0m, in [0;36m<cell line: 1>[1;34m()[0m
[1;32m----> 1[0m [43merr[49m
[0;32m      2[0m fig, ax [38;5;241m=[39m plt[38;5;241m.[39msubplots()
[0;32m      3[0m point [38;5;241m=[39m ([38;5;241m0.1[39m, [38;5;241m0.2[39m)

[1;31mNameError[0m: name 'err' is not defined
NameError: name 'err' is not defined

