Traceback (most recent call last):
  File "C:\Users\zimme\miniconda3\envs\blm\lib\site-packages\jupyter_cache\executors\utils.py", line 51, in single_nb_execution
    executenb(
  File "C:\Users\zimme\miniconda3\envs\blm\lib\site-packages\nbclient\client.py", line 1204, in execute
    return NotebookClient(nb=nb, resources=resources, km=km, **kwargs).execute()
  File "C:\Users\zimme\miniconda3\envs\blm\lib\site-packages\nbclient\util.py", line 84, in wrapped
    return just_run(coro(*args, **kwargs))
  File "C:\Users\zimme\miniconda3\envs\blm\lib\site-packages\nbclient\util.py", line 62, in just_run
    return loop.run_until_complete(coro)
  File "C:\Users\zimme\miniconda3\envs\blm\lib\asyncio\base_events.py", line 646, in run_until_complete
    return future.result()
  File "C:\Users\zimme\miniconda3\envs\blm\lib\site-packages\nbclient\client.py", line 663, in async_execute
    await self.async_execute_cell(
  File "C:\Users\zimme\miniconda3\envs\blm\lib\site-packages\nbclient\client.py", line 965, in async_execute_cell
    await self._check_raise_for_error(cell, cell_index, exec_reply)
  File "C:\Users\zimme\miniconda3\envs\blm\lib\site-packages\nbclient\client.py", line 862, in _check_raise_for_error
    raise CellExecutionError.from_cell_and_msg(cell, exec_reply_content)
nbclient.exceptions.CellExecutionError: An error occurred while executing the following cell:
------------------
import matplotlib.pyplot as plt
import scipy.signal as signal
#
fs=96000
xx1=tonal(fs,1,lfm(1000,5000,5,fs))
xx2=tonal(fs,1,sinfm(2000,1000,3,2,fs))


nw=1024
nover=nw//2
nfft=nw*4
f1,t1,Q1 = signal.stft(xx1,fs=fs,nperseg=nw,noverlap=nover,nfft=nfft)#,
f2,t2,Q2 = signal.stft(xx2,fs=fs,nperseg=nw,noverlap=nover,nfft=nfft)#,

ext1=[t1[0],t1[-1],f1[0]/1000,f1[-1]/1000]
ext2=[t2[0],t2[-1],f2[0]/1000,f2[-1]/1000]

plt.subplot(211)
plt.imshow(np.abs(Q1), origin='lower', aspect='auto',extent=ext)
plt.ylim(0,10)
plt.grid(True)
plt.subplot(212)
plt.imshow(np.abs(Q2), origin='lower', aspect='auto',extent=ext)
plt.ylim(0,10)
plt.grid(True)
plt.show()

------------------

[1;31m---------------------------------------------------------------------------[0m
[1;31mNameError[0m                                 Traceback (most recent call last)
Input [1;32mIn [3][0m, in [0;36m<cell line: 19>[1;34m()[0m
[0;32m     16[0m ext2[38;5;241m=[39m[t2[[38;5;241m0[39m],t2[[38;5;241m-[39m[38;5;241m1[39m],f2[[38;5;241m0[39m][38;5;241m/[39m[38;5;241m1000[39m,f2[[38;5;241m-[39m[38;5;241m1[39m][38;5;241m/[39m[38;5;241m1000[39m]
[0;32m     18[0m plt[38;5;241m.[39msubplot([38;5;241m211[39m)
[1;32m---> 19[0m plt[38;5;241m.[39mimshow(np[38;5;241m.[39mabs(Q1), origin[38;5;241m=[39m[38;5;124m'[39m[38;5;124mlower[39m[38;5;124m'[39m, aspect[38;5;241m=[39m[38;5;124m'[39m[38;5;124mauto[39m[38;5;124m'[39m,extent[38;5;241m=[39m[43mext[49m)
[0;32m     20[0m plt[38;5;241m.[39mylim([38;5;241m0[39m,[38;5;241m10[39m)
[0;32m     21[0m plt[38;5;241m.[39mgrid([38;5;28;01mTrue[39;00m)

[1;31mNameError[0m: name 'ext' is not defined
NameError: name 'ext' is not defined

